<?xml version="1.0" encoding="utf-8"?>
<robot name="hexapod">
  <link name="base_link">
    <inertial>
      <origin xyz="0 3.19534983082694E-17 0.515" rpy="0 0 0"/>
      <mass value="10.3552543883176"/>
      <inertia ixx="0.341004715450806" ixy="3.34578014165449E-17" ixz="2.99120712525083E-19" iyy="0.341004715450806" iyz="5.80217568869195E-19" izz="0.680456142743365"/>
    </inertial>
    
    <visual>
      <origin xyz="0 0 0" rpy="0 0 0"/>
      <geometry>
        <mesh filename="file://$(find robot_description)/meshes/base_link.STL"/>
      </geometry>
      <material name=""/>
    </visual>
    
    <collision>
      <origin xyz="0 0 0" rpy="0 0 0"/>
      <geometry>
        <mesh filename="file://$(find robot_description)/meshes/base_link.STL"/>
      </geometry>
    </collision>
  </link>

  <link name="L11">
    <inertial>
      <origin xyz="-0.000496539974013388 3.88355542169094E-10 -0.164643358154885" rpy="0 0 0"/>
      <mass value="1.92360326221169"/>
      <inertia ixx="0.00460813307678477" ixy="-6.01753269609262E-11" ixz="-9.07639273146896E-06" iyy="0.00454011742708446" iyz="-5.79907114243254E-11" izz="0.00508931854124723"/>
    </inertial>
    
    <visual>
      <origin xyz="0 0 0" rpy="0 0 0"/>
      <geometry>
        <mesh filename="file://$(find robot_description)/meshes/L11.STL"/>
      </geometry>
      <material name=""/>
    </visual>

    <collision>
      <origin xyz="0 0 0" rpy="0 0 0"/>
      <geometry>
        <mesh filename="file://$(find robot_description)/meshes/L11.STL"/>
      </geometry>
    </collision>
  </link>

  <joint name="J11" type="revolute">
    <origin xyz="0.303108891324554 0.175 0.75" rpy="0 0 0.523598775598296"/>
    <parent link="base_link"/>
    <child link="L11"/>
    <axis xyz="0 0 -1"/>
    <limit lower="-3.1416" upper="3.1416" effort="10000" velocity="10000"/>
  </joint>
  
  <link name="L12">
    <inertial>
      <origin xyz="0.247487373415291 0.247487373415292 -0.00206006865928844" rpy="0 0 0" />
      <mass value="9.70992368814396" />
      <inertia ixx="0.462558932733434" ixy="-0.436139273060991" ixz="-1.13809997952198E-16" iyy="0.462558932733431" iyz="-2.84703396383867E-17" izz="0.897008391500982" />
    </inertial>

    <visual>
      <origin xyz="0 0 0" rpy="0 0 0" />
      <geometry>
        <mesh filename="file://$(find robot_description)/meshes/L12.STL" />
      </geometry>
      <material name="" />
    </visual>

    <collision>
      <origin xyz="0 0 0" rpy="0 0 0" />
      <geometry>
        <mesh filename="file://$(find robot_description)/meshes/L12.STL" />
      </geometry>
    </collision>
  </link>
  
  <joint name="J12" type="revolute">
    <origin xyz="0 0 0" rpy="1.5707963267949 0 0" />
    <parent link="L11" />
    <child link="L12" />
    <axis xyz="0 0 -1" />
    <limit lower="-3.1416" upper="3.1416" effort="10000" velocity="10000" />
  </joint>

  <link name="L13">
    <inertial>
      <origin xyz="0.675 0 -9.80960396928888E-17" rpy="0 0 0" />
      <mass value="1.97482300164693" />
      <inertia ixx="0.000734196900494079" ixy="-9.20803201537188E-19" ixz="2.85561209105843E-17" iyy="0.198324286729428" iyz="-6.48570248351833E-31" izz="0.198762260179675" />
    </inertial>

    <visual>
      <origin xyz="0 0 0" rpy="0 0 0"/>
      <geometry>
        <mesh filename="file://$(find robot_description)/meshes/L13.STL"/>
      </geometry>
      <material name="SilverFoil">
        <script>
          <uri>model://materials/scripts/</uri>
          <uri>model://materials/textures/</uri>
          <name>Gazebo/SilverFoil</name>
        </script>
      </material>
    </visual>

    <collision>
      <origin xyz="0 0 0" rpy="0 0 0" />
      <geometry>
        <mesh filename="file://$(find robot_description)/meshes/L13.STL"/>
      </geometry>
    </collision>
  </link>

  <gazebo reference="L13">
    <material>Gazebo/SilverFoil</material>
  </gazebo>

  <joint name="J13" type="revolute">
    <origin xyz="0.49497 0.49497 0" rpy="0 0 -1.5708" />
    <parent link="L12" />
    <child link="L13" />
    <axis xyz="0 0 -1" />
    <limit lower="-3.1416" upper="3.1416" effort="10000" velocity="10000" />
  </joint>

  <link name="L21">
    <inertial>
      <origin xyz="-0.000496540203313467 4.22521449926359E-10 -0.164643358346364" rpy="0 0 0" />
      <mass value="1.923603259491" />
      <inertia ixx="0.00460813318905677" ixy="-6.17968550869755E-11" ixz="-9.07636083787613E-06" iyy="0.00454011737194526" iyz="-5.86058029430777E-11" izz="0.0050893186493335" />
    </inertial>

    <visual>
      <origin xyz="0 0 0" rpy="0 0 0" />
      <geometry>
        <mesh filename="file://$(find robot_description)/meshes/L21.STL" />
      </geometry>
      <material name="" />
    </visual>

    <collision>
      <origin xyz="0 0 0" rpy="0 0 0" />
      <geometry>
        <mesh filename="file://$(find robot_description)/meshes/L21.STL" />
      </geometry>
    </collision>
  </link>

  <joint name="J21" type="revolute">
    <origin xyz="0 0.35 0.75" rpy="0 0 1.5707963267949" />
    <parent link="base_link" />
    <child link="L21" />
    <axis xyz="0 0 -1" />
    <limit lower="-3.1416" upper="3.1416" effort="10000" velocity="10000" />
  </joint>

  <link name="L22">
    <inertial>
      <origin xyz="0.35 0 -0.00206006865928853" rpy="0 0 0" />
      <mass value="9.70992368814396" />
      <inertia ixx="0.026419659672442" ixy="6.93889390390723E-17" ixz="2.61196437496758E-17" iyy="0.898698205794423" iyz="-6.34105680926242E-19" izz="0.897008391500982" />
    </inertial>
    
    <visual>
      <origin xyz="0 0 0" rpy="0 0 0" />
      <geometry>
        <mesh filename="file://$(find robot_description)/meshes/L22.STL" />
      </geometry>
      <material name="" />
    </visual>
    
    <collision>
      <origin xyz="0 0 0" rpy="0 0 0" />
      <geometry>
        <mesh filename="file://$(find robot_description)/meshes/L22.STL" />
      </geometry>
    </collision>
  </link>

  <joint name="J22" type="revolute">
    <origin xyz="0 0 0" rpy="1.5707963267949 -0.78539816339745 0" />
    <parent link="L21" />
    <child link="L22" />
    <axis xyz="0 0 -1" />
    <limit lower="-3.1416" upper="3.1416" effort="10000" velocity="10000" />
  </joint>

  <link name="L23">
    <inertial>
      <origin xyz="0.675 0 -9.44121348005163E-17" rpy="0 0 0" />
      <mass value="1.97482300164693" />
      <inertia ixx="0.000734196900494078" ixy="-9.59768208917418E-18" ixz="2.81800609278589E-17" iyy="0.198324286729428" iyz="8.89346193258841E-20" izz="0.198762260179675" />
    </inertial>

    <visual>
      <origin xyz="0 0 0" rpy="0 0 0" />
      <geometry>
        <mesh filename="file://$(find robot_description)/meshes/L23.STL" />
      </geometry>
      <material name="" />
    </visual>

    <collision>
      <origin xyz="0 0 0" rpy="0 0 0" />
      <geometry>
        <mesh filename="file://$(find robot_description)/meshes/L23.STL" />
      </geometry>
    </collision>
  </link>

  <joint name="J23" type="revolute">
    <origin xyz="0.7 0 0" rpy="0 0 -2.35619449019235" />
    <parent link="L22" />
    <child link="L23" />
    <axis xyz="0 0 -1" />
    <limit lower="-3.1416" upper="3.1416" effort="10000" velocity="10000" />
  </joint>

  <link name="L31">
    <inertial>
      <origin xyz="-0.000496539975061716 3.72729247794499E-10 -0.164643358158046" rpy="0 0 0" />
      <mass value="1.92360326228292" />
      <inertia ixx="0.0046081330778192" ixy="-5.47053359685893E-11" ixz="-9.07639215600673E-06" iyy="0.00454011742605988" iyz="-4.98175271091862E-11" izz="0.00508931854270639" />
    </inertial>

    <visual>
      <origin xyz="0 0 0" rpy="0 0 0" />
      <geometry>
        <mesh filename="file://$(find robot_description)/meshes/L31.STL" />
      </geometry>
      <material name="" />
    </visual>

    <collision>
      <origin xyz="0 0 0" rpy="0 0 0" />
      <geometry>
        <mesh filename="file://$(find robot_description)/meshes/L31.STL" />
      </geometry>
    </collision>
  </link>
  
  <joint name="J31" type="revolute">
    <origin xyz="-0.303108891324554 0.174999999999998 0.75" rpy="0 0 2.6179938779915" />
    <parent link="base_link" />
    <child link="L31" />
    <axis xyz="0 0 -1" />
    <limit lower="-3.1416" upper="3.1416" effort="10000" velocity="10000" />
  </joint>

  <link name="L32">
    <inertial>
      <origin xyz="0.35 0 -0.00206006865928842" rpy="0 0 0" />
      <mass value="9.70992368814396" />
      <inertia ixx="0.0264196596724418" ixy="-2.60208521396521E-18" ixz="6.58204367911844E-18" iyy="0.898698205794423" iyz="1.38350826712278E-16" izz="0.897008391500982" />
    </inertial>

    <visual>
      <origin xyz="0 0 0" rpy="0 0 0" />
      <geometry>
        <mesh filename="file://$(find robot_description)/meshes/L32.STL" />
      </geometry>
      <material name="" />
    </visual>
    
    <collision>
      <origin xyz="0 0 0" rpy="0 0 0" />
      <geometry>
        <mesh filename="file://$(find robot_description)/meshes/L32.STL" />
      </geometry>
    </collision>
  </link>

  <joint name="J32" type="revolute">
    <origin xyz="0 0 0" rpy="1.5707963267949 -0.78539816339745 0" />
    <parent link="L31" />
    <child link="L32" />
    <axis xyz="0 0 -1" />
    <limit lower="-3.1416" upper="3.1416" effort="10000" velocity="10000" />
  </joint>

  <link name="L33">
    <inertial>
      <origin xyz="0.675 0 -9.80960396928884E-17" rpy="0 0 0" />
      <mass value="1.97482300164692" />
      <inertia ixx="0.000734196900494076" ixy="-1.32501486996949E-17" ixz="2.34711887754194E-17" iyy="0.198324286729427" iyz="-1.38777878078151E-17" izz="0.198762260179674" />
    </inertial>

    <visual>
      <origin xyz="0 0 0" rpy="0 0 0" />
      <geometry>
        <mesh filename="file://$(find robot_description)/meshes/L33.STL" />
      </geometry>
      <material name="" />
    </visual>

    <collision>
      <origin xyz="0 0 0" rpy="0 0 0" />
      <geometry>
        <mesh filename="file://$(find robot_description)/meshes/L33.STL" />
      </geometry>
    </collision>
  </link>

  <joint name="J33" type="revolute">
    <origin xyz="0.7 0 0" rpy="0 0 -2.35619449019235" />
    <parent link="L32" />
    <child link="L33" />
    <axis xyz="0 0 -1" />
    <limit lower="-3.1416" upper="3.1416" effort="10000" velocity="10000" />
  </joint>

  <link name="L41">
    <inertial>
      <origin xyz="-0.000496539974013444 3.88355537599323E-10 -0.164643358154885" rpy="0 0 0" />
      <mass value="1.92360326221169" />
      <inertia ixx="0.00460813307678477" ixy="-6.01753271778926E-11" ixz="-9.07639273146965E-06" iyy="0.00454011742708446" iyz="-5.79907113236288E-11" izz="0.00508931854124723" />
    </inertial>

    <visual>
      <origin xyz="0 0 0" rpy="0 0 0" />
      <geometry>
        <mesh filename="file://$(find robot_description)/meshes/L41.STL" />
      </geometry>
      <material name="" />
    </visual>

    <collision>
      <origin xyz="0 0 0" rpy="0 0 0" />
      <geometry>
        <mesh filename="file://$(find robot_description)/meshes/L41.STL" />
      </geometry>
    </collision>
  </link>

  <joint name="J41" type="revolute">
    <origin xyz="-0.30311 -0.175 0.75" rpy="0 0 -2.618" />
    <parent link="base_link" />
    <child link="L41" />
    <axis xyz="0 0 -1" />
    <limit lower="-3.1416" upper="3.1416" effort="10000" velocity="10000" />
  </joint>

  <link name="L42">
    <inertial>
      <origin xyz="0.35 5.55111512312578E-17 -0.00206006865928859" rpy="0 0 0" />
      <mass value="9.70992368814396" />
      <inertia ixx="0.026419659672442" ixy="2.21177243187043E-16" ixz="-5.33785710449549E-18" iyy="0.898698205794423" iyz="4.58437545178013E-18" izz="0.897008391500982" />
    </inertial>

    <visual>
      <origin xyz="0 0 0" rpy="0 0 0" />
      <geometry>
        <mesh filename="file://$(find robot_description)/meshes/L42.STL" />
      </geometry>
      <material name="" />
    </visual>

    <collision>
      <origin xyz="0 0 0" rpy="0 0 0" />
      <geometry>
        <mesh filename="file://$(find robot_description)/meshes/L42.STL" />
      </geometry>
    </collision>
  </link>

  <joint name="J42" type="revolute">
    <origin xyz="0 0 0" rpy="-1.5707963267949 -0.78539816339745 0" />
    <parent link="L41" />
    <child link="L42" />
    <axis xyz="0 0 -1" />
    <limit lower="-3.1416" upper="3.1416" effort="10000" velocity="10000" />
  </joint>

  <link name="L43">
    <inertial>
      <origin xyz="0.675 1.11022302462516E-16 1.33925684875783E-16" rpy="0 0 0" />
      <mass value="1.97482300164692" />
      <inertia ixx="0.000734196900494077" ixy="5.95736064771951E-21" ixz="-3.23349261066495E-17" iyy="0.198324286729428" iyz="1.38777878078157E-17" izz="0.198762260179675" />
    </inertial>

    <visual>
      <origin xyz="0 0 0" rpy="0 0 0" />
      <geometry>
        <mesh filename="file://$(find robot_description)/meshes/L43.STL" />
      </geometry>
      <material name="" />
    </visual>

    <collision>
      <origin xyz="0 0 0" rpy="0 0 0" />
      <geometry>
        <mesh filename="file://$(find robot_description)/meshes/L43.STL" />
      </geometry>
    </collision>
  </link>
  
  <joint name="J43" type="revolute">
    <origin xyz="0.7 0 0" rpy="0 0 2.35619449019235" />
    <parent link="L42" />
    <child link="L43" />
    <axis xyz="0 0 1" />
    <limit lower="-3.1416" upper="3.1416" effort="10000" velocity="10000" />
  </joint>
  
  <link name="L51">
    <inertial>
      <origin xyz="-0.000496540203313411 4.22521395908064E-10 -0.164643358346364" rpy="0 0 0" />
      <mass value="1.923603259491" />
      <inertia ixx="0.00460813318905677" ixy="-6.17968552882557E-11" ixz="-9.07636083787628E-06" iyy="0.00454011737194526" iyz="-5.8605802961426E-11" izz="0.0050893186493335" />
    </inertial>

    <visual>
      <origin xyz="0 0 0" rpy="0 0 0" />
      <geometry>
        <mesh filename="file://$(find robot_description)/meshes/L51.STL" />
      </geometry>
      <material name="" />
    </visual>

    <collision>
      <origin xyz="0 0 0" rpy="0 0 0" />
      <geometry>
        <mesh filename="file://$(find robot_description)/meshes/L51.STL" />
      </geometry>
    </collision>
  </link>
  
  <joint name="J51" type="revolute">
    <origin xyz="0 -0.35 0.75" rpy="0 0 -1.5708" />
    <parent link="base_link" />
    <child link="L51" />
    <axis xyz="0 0 -1" />
    <limit lower="-3.1416" upper="3.1416" effort="10000" velocity="10000" />
  </joint>
  
  <link name="L52">
    <inertial>
      <origin xyz="0.35 -1.66533453693773E-16 -0.00206006865928855" rpy="0 0 0" />
      <mass value="9.70992368814396" />
      <inertia ixx="0.0264196596724418" ixy="1.00613961606655E-16" ixz="5.7621849463952E-17" iyy="0.898698205794422" iyz="-5.43821073850043E-18" izz="0.897008391500981" />
    </inertial>

    <visual>
      <origin xyz="0 0 0" rpy="0 0 0" />
      <geometry>
        <mesh filename="file://$(find robot_description)/meshes/L52.STL" />
      </geometry>
      <material name="" />
    </visual>

    <collision>
      <origin xyz="0 0 0" rpy="0 0 0" />
      <geometry>
        <mesh filename="file://$(find robot_description)/meshes/L52.STL" />
      </geometry>
    </collision>
  </link>

  <joint name="J52" type="revolute">
    <origin xyz="0 0 0" rpy="-1.5707963267949 -0.78539816339745 0" />
    <parent link="L51" />
    <child link="L52" />
    <axis xyz="0 0 -1" />
    <limit lower="-3.1416" upper="3.1416" effort="10000" velocity="10000" />
  </joint>

  <link name="L53">
    <inertial>
      <origin xyz="0.675 1.11022302462516E-16 1.01113686938468E-16" rpy="0 0 0" />
      <mass value="1.97482300164692" />
      <inertia ixx="0.000734196900494076" ixy="1.25688199992843E-17" ixz="-2.61407711129973E-17" iyy="0.198324286729427" iyz="-2.87503605153375E-18" izz="0.198762260179674" />
    </inertial>
    
    <visual>
      <origin xyz="0 0 0" rpy="0 0 0" />
      <geometry>
        <mesh filename="file://$(find robot_description)/meshes/L53.STL" />
      </geometry>
      <material name="" />
    </visual>

    <collision>
      <origin xyz="0 0 0" rpy="0 0 0" />
      <geometry>
        <mesh filename="file://$(find robot_description)/meshes/L53.STL" />
      </geometry>
    </collision>
  </link>

  <joint name="J53" type="revolute">
    <origin xyz="0.7 0 0" rpy="0 0 2.35619449019235" />
    <parent link="L52" />
    <child link="L53" />
    <axis xyz="0 0 1" />
    <limit lower="-3.1416" upper="3.1416" effort="10000" velocity="10000" />
  </joint>

  <link name="L61">
    <inertial>
      <origin xyz="-0.000496539975061827 3.72729398327905E-10 -0.164643358158046" rpy="0 0 0" />
      <mass value="1.92360326228292" />
      <inertia ixx="0.00460813307781921" ixy="-5.47053355307591E-11" ixz="-9.07639215600687E-06" iyy="0.00454011742605988" iyz="-4.98175276310862E-11" izz="0.00508931854270639" />
    </inertial>
    
    <visual>
      <origin xyz="0 0 0" rpy="0 0 0" />
      <geometry>
        <mesh filename="file://$(find robot_description)/meshes/L61.STL" />
      </geometry>
      <material name="" />
    </visual>
    
    <collision>
      <origin xyz="0 0 0" rpy="0 0 0"/>
      <geometry>
        <mesh filename="file://$(find robot_description)/meshes/L61.STL"/>
      </geometry>
    </collision>
  </link>

  <joint name="J61" type="revolute">
    <origin xyz="0.303108891324554 -0.175 0.75" rpy="0 0 -0.523598775598303"/>
    <parent link="base_link"/>
    <child link="L61"/>
    <axis xyz="0 0 -1"/>
    <limit lower="-3.1416" upper="3.1416" effort="10000" velocity="10000"/>
  </joint>

  <link name="L62">
    <inertial>
      <origin xyz="0.35 -1.11022302462516E-16 -0.00206006865928856" rpy="0 0 0"/>
      <mass value="9.70992368814396"/>
      <inertia ixx="0.026419659672442" ixy="3.29597460435593E-17" ixz="2.84381851857674E-17" iyy="0.898698205794423" iyz="-8.03660093797984E-17" izz="0.897008391500982"/>
    </inertial>
    
    <visual>
      <origin xyz="0 0 0" rpy="0 0 0"/>
      <geometry>
        <mesh filename="file://$(find robot_description)/meshes/L62.STL"/>
      </geometry>
      <material name=""/>
    </visual>
    
    <collision>
      <origin xyz="0 0 0" rpy="0 0 0"/>
      <geometry>
        <mesh filename="file://$(find robot_description)/meshes/L62.STL"/>
      </geometry>
    </collision>
  </link>

  <joint name="J62" type="revolute">
    <origin xyz="0 0 0" rpy="-1.5707963267949 -0.78539816339745 0"/>
    <parent link="L61"/>
    <child link="L62"/>
    <axis xyz="0 0 -1"/>
    <limit lower="-3.1416" upper="3.1416" effort="10000" velocity="10000"/>
  </joint>
  
  <link name="L63">
    <inertial>
      <origin xyz="0.675 -1.11022302462516E-16 2.29033824132673E-17" rpy="0 0 0"/>
      <mass value="1.97482300164692"/>
      <inertia ixx="0.000734196900494078" ixy="1.28431943223828E-17" ixz="-2.04690208235314E-17" iyy="0.198324286729428" iyz="-1.38777878078133E-17" izz="0.198762260179675"/>
    </inertial>
    
    <visual>
      <origin xyz="0 0 0" rpy="0 0 0"/>
      <geometry>
        <mesh filename="file://$(find robot_description)/meshes/L63.STL"/>
      </geometry>
      <material name=""/>
    </visual>

    <collision>
      <origin xyz="0 0 0" rpy="0 0 0"/>
      <geometry>
        <mesh filename="file://$(find robot_description)/meshes/L63.STL"/>
      </geometry>
    </collision>
  </link>

  <joint name="J63" type="revolute">
    <origin xyz="0.7 0 0" rpy="0 0 2.35619449019235"/>
    <parent link="L62"/>
    <child link="L63"/>
    <axis xyz="0 0 1"/>
    <limit lower="-3.1416" upper="3.1416" effort="10000" velocity="10000"/>
  </joint>
</robot>